<robot name="scora_ind">
  <link name="world"/>
  <link name="base_link">
    <inertial>
      <origin
        xyz="-0.020576 -3.8955E-05 0.30367"
        rpy="0 0 0" />
      <mass
        value="10.627" />
      <inertia
        ixx="0.62518"
        ixy="-3.1226E-05"
        ixz="-0.038833"
        iyy="0.63836"
        iyz="-8.6911E-05"
        izz="0.038067" />
    </inertial>
    <visual>
      <origin
        xyz="0 0 0"
        rpy="0 0 0" />
      <geometry>
        <mesh
          filename="package://scora_ind/base_link.STL" />
      </geometry>
      <material name="white">
        <color rgba="1 1 1 1" />
      </material>
    </visual>
    <collision>
      <origin
        xyz="0 0 0"
        rpy="0 0 0" />
      <geometry>
        <mesh
          filename="package://scora_ind/base_link.STL" />
      </geometry>
    </collision>
  </link>
  <joint name="base_joint" type="fixed">
    <parent link="world"/>
    <child link="base_link"/>
  </joint>
  <link name="link_1">
    <inertial>
      <origin
        xyz="0.12615 1.1102E-16 0.071467"
        rpy="0 0 0" />
      <mass
        value="9.9747" />
      <inertia
        ixx="0.035087"
        ixy="-1.8459E-17"
        ixz="-0.0077194"
        iyy="0.15551"
        iyz="-7.2486E-19"
        izz="0.15043" />
    </inertial>
    <visual>
      <origin
        xyz="0 0 0"
        rpy="0 0 0" />
      <geometry>
        <mesh
          filename="package://scora_ind/link_1.STL" />
      </geometry>
      <material
        name="white">
      </material>
    </visual>
    <collision>
      <origin
        xyz="0 0 0"
        rpy="0 0 0" />
      <geometry>
        <mesh
          filename="package://scora_ind/link_1.STL" />
      </geometry>
    </collision>
  </link>
  <joint name="link_1_to_base_link" type="revolute">
    <origin
      xyz="-0.0055 0 0.588"
      rpy="0 0 -0.0062122" />
    <parent
      link="base_link" />
    <child
      link="link_1" />
    <axis
      xyz="0 0 1" />
    <limit
      lower="-2.125"
      upper="2.125"
      effort="1000"
      velocity="0.5" />
  </joint>
  <link name="link_2">
    <inertial>
      <origin
        xyz="0.115 0 -0.065"
        rpy="0 0 0" />
      <mass
        value="7.9815" />
      <inertia
        ixx="0.023223"
        ixy="8.0231E-18"
        ixz="-3.9465E-20"
        iyy="0.089988"
        iyz="2.9579E-21"
        izz="0.09073" />
    </inertial>
    <visual>
      <origin
        xyz="0 0 0"
        rpy="0 0 0" />
      <geometry>
        <mesh
          filename="package://scora_ind/link_2.STL" />
      </geometry>
      <material
        name="white">
      </material>
    </visual>
    <collision>
      <origin
        xyz="0 0 0"
        rpy="0 0 0" />
      <geometry>
        <mesh
          filename="package://scora_ind/link_2.STL" />
      </geometry>
    </collision>
  </link>
  <joint name="link_2_to_link_1" type="revolute">
    <origin
      xyz="0.27 0 0"
      rpy="0 0 0" />
    <parent
      link="link_1" />
    <child
      link="link_2" />
    <axis
      xyz="0 0 1" />
    <limit
      lower="-2"
      upper="2"
      effort="1000"
      velocity="0.5" />
  </joint>
  <link name="link_3">
    <inertial>
      <origin
        xyz="-7.3636E-06 4.1493E-06 0.020712"
        rpy="0 0 0" />
      <mass
        value="1.5933" />
      <inertia
        ixx="0.034764"
        ixy="-2.8205E-07"
        ixz="-3.0788E-06"
        iyy="0.034763"
        iyz="-3.3818E-06"
        izz="0.00078745" />
    </inertial>
    <visual>
      <origin
        xyz="0 0 0"
        rpy="0 0 0" />
      <geometry>
        <mesh
          filename="package://scora_ind/link_3.STL" />
      </geometry>
      <material name="black">
        <color rgba="0 0 0 1" />
      </material>
    </visual>
    <collision>
      <origin
        xyz="0 0 0"
        rpy="0 0 0" />
      <geometry>
        <mesh
          filename="package://scora_ind/link_3.STL" />
      </geometry>
    </collision>
  </link>
  <joint name="link_3_to_link_2" type="prismatic">
    <origin
      xyz="0.23 0 0"
      rpy="0 0 0" />
    <parent
      link="link_2" />
    <child
      link="link_3" />
    <axis
      xyz="0 0 1" />
    <limit
      lower="-0.12"
      upper="0"
      effort="1000"
      velocity="0.5" />
  </joint>
  <link name="link_4">
    <inertial>
      <origin
        xyz="3.5527E-15 -2.4294E-06 0.028021"
        rpy="0 0 0" />
      <mass
        value="0.53644" />
      <inertia
        ixx="0.00067573"
        ixy="1.2756E-18"
        ixz="4.432E-19"
        iyy="0.00099074"
        iyz="3.8907E-09"
        izz="0.00097636" />
    </inertial>
    <visual>
      <origin
        xyz="0 0 0"
        rpy="0 0 0" />
      <geometry>
        <mesh
          filename="package://scora_ind/link_4.STL" />
      </geometry>
      <material name="plateado">
        <color rgba="0.753 0.753 0.753 1" />
      </material>
    </visual>
    <collision>
      <origin
        xyz="0 0 0"
        rpy="0 0 0" />
      <geometry>
        <mesh
          filename="package://scora_ind/link_4.STL" />
      </geometry>
    </collision>
  </link>
  <joint name="link_4_to_link_3" type="revolute">
    <origin
      xyz="0 0 -0.3478"
      rpy="0 0 0" />
    <parent
      link="link_3" />
    <child
      link="link_4" />
    <axis
      xyz="0 0 1" />
    <limit
      lower="0"
      upper="10"
      effort="1000"
      velocity="0.5" />
  </joint>
  <link name="gripper_left">
    <inertial>
      <origin
        xyz="0.0020758 -0.012378 -2.3708E-07"
        rpy="0 0 0" />
      <mass
        value="0.046306" />
      <inertia
        ixx="4.3367E-05"
        ixy="8.8996E-07"
        ixz="7.9718E-11"
        iyy="3.9069E-05"
        iyz="-1.1777E-10"
        izz="6.6885E-06" />
    </inertial>
    <visual>
      <origin
        xyz="0 0 0"
        rpy="0 0 0" />
      <geometry>
        <mesh
          filename="package://scora_ind/gripper_left.STL" />
      </geometry>
      <material
        name="plateado">
        <color
          rgba="0.753 0.753 0.753 1" />
      </material>
    </visual>
    <collision>
      <origin
        xyz="0 0 0"
        rpy="0 0 0" />
      <geometry>
        <mesh
          filename="package://scora_ind/gripper_left.STL" />
      </geometry>
    </collision>
  </link>
  <joint name="gripper_left_to_link_4" type="prismatic">
    <origin
      xyz="-0.04 4.2729E-05 0"
      rpy="1.5708 0 0" />
    <parent
      link="link_4" />
    <child
      link="gripper_left" />
    <axis
      xyz="1 0 0" />
    <limit
      lower="0"
      upper="0.027"
      effort="1000"
      velocity="0.5" />
  </joint>
  <link name="gripper_right">
    <inertial>
      <origin
        xyz="0.0020758 -0.012378 -2.3708E-07"
        rpy="0 0 0" />
      <mass
        value="0.046306" />
      <inertia
        ixx="4.3367E-05"
        ixy="8.8996E-07"
        ixz="7.9718E-11"
        iyy="3.9069E-05"
        iyz="-1.1777E-10"
        izz="6.6885E-06" />
    </inertial>
    <visual>
      <origin
        xyz="0 0 0"
        rpy="0 0 0" />
      <geometry>
        <mesh
          filename="package://scora_ind/gripper_right.STL" />
      </geometry>
      <material
        name="plateado">
        <color
          rgba="0.753 0.753 0.753 1" />
      </material>
    </visual>
    <collision>
      <origin
        xyz="0 0 0"
        rpy="0 0 0" />
      <geometry>
        <mesh
          filename="package://scora_ind/gripper_right.STL" />
      </geometry>
    </collision>
  </link>
  <joint name="gripper_right_to_link_4" type="prismatic">
    <origin
      xyz="0.04 -4.8156E-05 0"
      rpy="1.5708 0 -3.1416" />
    <parent
      link="link_4" />
    <child
      link="gripper_right" />
    <axis
      xyz="1 0 0" />
    <limit
      lower="0"
      upper="0.027"
      effort="1000"
      velocity="0.5" />
  </joint>
  <link name="link2_top">
    <inertial>
      <origin
        xyz="0.0799999999999983 0.137075534561327 -3.33066907387547E-16"
        rpy="0 0 0" />
      <mass
        value="3.92307386569457" />
      <inertia
        ixx="0.0285329210592484"
        ixy="-1.34166425079099E-19"
        ixz="-1.6737371037745E-17"
        iyy="0.00814530909474389"
        iyz="-7.42066745382684E-19"
        izz="0.032806125366484" />
    </inertial>
    <visual>
      <origin
        xyz="0 0 0"
        rpy="0 0 0" />
      <geometry>
        <mesh
          filename="package://scora_ind/link2_top.STL" />
      </geometry>
      <material
        name="blue">
        <color
          rgba="0 0 0.5 1" />
      </material>
    </visual>
    <collision>
      <origin
        xyz="0 0 0"
        rpy="0 0 0" />
      <geometry>
        <mesh
          filename="package://scora_ind/link2_top.STL" />
      </geometry>
    </collision>
  </link>
  <joint name="link2_top_to_link_2" type="fixed">
    <origin
      xyz="0.115 0 0"
      rpy="1.5708 0 0" />
    <parent
      link="link_2" />
    <child
      link="link2_top" />
    <axis
      xyz="0 0 0" />
  </joint>
  <link name="link2_bottom">
    <inertial>
      <origin
        xyz="-0.00644500992563835 -0.0188050084111309 1.11022302462516E-16"
        rpy="0 0 0" />
      <mass
        value="1.95123434278269" />
      <inertia
        ixx="0.00331961154325414"
        ixy="-0.000805962516648948"
        ixz="-5.93499045482143E-17"
        iyy="0.0226992510293057"
        iyz="-2.67069488269281E-18"
        izz="0.0200921960559996" />
    </inertial>
    <visual>
      <origin
        xyz="0 0 0"
        rpy="0 0 0" />
      <geometry>
        <mesh
          filename="package://scora_ind/link2_bottom.STL" />
      </geometry>
      <material name="blue">
      </material>
    </visual>
    <collision>
      <origin
        xyz="0 0 0"
        rpy="0 0 0" />
      <geometry>
        <mesh
          filename="package://scora_ind/link2_bottom.STL" />
      </geometry>
    </collision>
  </link>
  <joint name="link2_bottom_to_link_2" type="fixed">
    <origin
      xyz="0.115 0 -0.13"
      rpy="1.5708 0 -3.1416" />
    <parent
      link="link_2" />
    <child
      link="link2_bottom" />
    <axis
      xyz="0 0 0" />
  </joint>
  <link name="link_top">
    <inertial>
      <origin
        xyz="-0.00753322423281588 -0.00296996989495923 0"
        rpy="0 0 0" />
      <mass
        value="2.409257353011" />
      <inertia
        ixx="0.00448015427343087"
        ixy="-0.00154361040098474"
        ixz="-1.12894245275948E-16"
        iyy="0.0379892781501379"
        iyz="-5.68697920786537E-18"
        izz="0.0351502203277833" />
    </inertial>
    <visual>
      <origin
        xyz="0 0 0"
        rpy="0 0 0" />
      <geometry>
        <mesh
          filename="package://scora_ind/link_top.STL" />
      </geometry>
      <material
        name="blue">
      </material>
    </visual>
    <collision>
      <origin
        xyz="0 0 0"
        rpy="0 0 0" />
      <geometry>
        <mesh
          filename="package://scora_ind/link_top.STL" />
      </geometry>
    </collision>
  </link>
  <joint name="link_top_to_link_1" type="fixed">
    <origin
      xyz="0.135 0 0.177"
      rpy="1.5708 0 -3.1416" />
    <parent
      link="link_1" />
    <child
      link="link_top" />
    <axis
      xyz="0 0 0" />
  </joint>
  <link name="Light_alarm">
    <inertial>
      <origin
        xyz="3.5527136788005E-15 0.0115884654215042 0"
        rpy="0 0 0" />
      <mass
        value="0.0722547774929001" />
      <inertia
        ixx="1.68268117221355E-05"
        ixy="1.34395172560721E-38"
        ixz="-8.38981686825007E-38"
        iyy="2.52954565738841E-05"
        iyz="-2.87777857228373E-22"
        izz="1.68268117221355E-05" />
    </inertial>
    <visual>
      <origin
        xyz="0 0 0"
        rpy="0 0 0" />
      <geometry>
        <mesh
          filename="package://scora_ind/Light_alarm.STL" />
      </geometry>
      <material
        name="red">
        <color
          rgba="0.8 0 0 1" />
      </material>
    </visual>
    <collision>
      <origin
        xyz="0 0 0"
        rpy="0 0 0" />
      <geometry>
        <mesh
          filename="package://scora_ind/Light_alarm.STL" />
      </geometry>
    </collision>
  </link>
  <joint name="Light_alarm_to_link_top" type="fixed">
    <origin
      xyz="0.135 0.04 0"
      rpy="0 0.0062122 0" />
    <parent
      link="link_top" />
    <child
      link="Light_alarm" />
    <axis
      xyz="0 0 0" />
  </joint>
</robot>